<?xml version="1.0"?>
<robot name="simple_5dof_robot">

  <link name="base_link">
    <visual>
      <geometry>
        <box size="0.2 0.2 0.05"/>
      </geometry>
      <material>
        <color rgba="0.8 0.8 0.8 1"/>
      </material>
    </visual>
    <collision>
      <geometry>
        <box size="0.2 0.2 0.05"/>
      </geometry>
    </collision>
  </link>

  <link name="link_1">
    <visual>
      <geometry>
        <box size="0.05 0.05 0.3"/>
      </geometry>
      <origin xyz="0 0 0.025" rpy="0 0 0"/>
      <material>
        <color rgba="0.8 0.2 0.2 1"/>
      </material>
    </visual>
    <collision>
      <geometry>
        <box size="0.05 0.05 0.3"/>
      </geometry>
      <origin xyz="0 0 0.025" rpy="0 0 0"/>
    </collision>
  </link>

  <joint name="joint_1" type="revolute">
    <parent link="base_link"/>
    <child link="link_1"/>
    <origin xyz="0 0 0.025" rpy="0 0 0"/>
    <axis xyz="0 0 1"/>
    <limit lower="-1" upper="1" effort="10" velocity="1"/>
  </joint>

  <link name="link_2">
    <visual>
      <geometry>
        <box size="0.05 0.05 0.3"/>
      </geometry>
      <origin xyz="0 0 0.125" rpy="0 0 0"/>
      <material>
        <color rgba="0.2 0.8 0.2 1"/>
      </material>
    </visual>
    <collision>
      <geometry>
        <box size="0.05 0.05 0.3"/>
      </geometry>
      <origin xyz="0 0 0.125" rpy="0 0 0"/>
    </collision>
  </link>

  <joint name="joint_2" type="revolute">
    <parent link="link_1"/>
    <child link="link_2"/>
    <origin xyz="0 0 0.3" rpy="1.5707 0 0"/>
    <axis xyz="1 0 0"/>
    <limit lower="-1.57" upper=".65" effort="10" velocity="1"/>
  </joint>

  <link name="link_3">
    <visual>
      <geometry>
        <box size="0.05 0.05 0.3"/>
      </geometry>
      <origin xyz="0 0 0.1" rpy="0 0 0"/>
      <material>
        <color rgba="0.2 0.2 0.8 1"/>
      </material>
    </visual>
    <collision>
      <geometry>
        <cylinder length="0.2" radius="0.04"/>
      </geometry>
      <origin xyz="0 0 0.1" rpy="0 0 0"/>
    </collision>
  </link>

  <joint name="joint_3" type="revolute">
    <parent link="link_2"/>
    <child link="link_3"/>
    <origin xyz="0 0 0.25" rpy="0 0 0"/>
    <axis xyz="0 0 1"/>
    <limit lower="-0.57" upper="1" effort="10" velocity="1"/>
  </joint>

  <link name="link_4">
    <visual>
      <geometry>
        <box size="0.05 0.05 0.3"/>
      </geometry>
      <origin xyz="0 0 0.075" rpy="0 0 0"/>
      <material>
        <color rgba="0.8 0.8 0.2 1"/>
      </material>
    </visual>
    <collision>
      <geometry>
        <cylinder length="0.15" radius="0.04"/>
      </geometry>
      <origin xyz="0 0 0.075" rpy="0 0 0"/>
    </collision>
  </link>

  <joint name="joint_4" type="revolute">
    <parent link="link_3"/>
    <child link="link_4"/>
    <origin xyz="0 0 0.2" rpy="-1.5707 0 0"/>
    <axis xyz="1 0 0"/>
    <limit lower="-1" upper="1" effort="10" velocity="1"/>
  </joint>

  <link name="end_effector_link">
    <visual>
      <geometry>
        <box size="0.05 0.05 0.05"/>
      </geometry>
      <origin xyz="0 0 0.05" rpy="0 0 0"/>
      <material>
        <color rgba="0.8 0.5 0.8 1"/>
      </material>
    </visual>
    <collision>
      <geometry>
        <box size="0.05 0.05 0.05"/>
      </geometry>
      <origin xyz="0 0 0.05" rpy="0 0 0"/>
    </collision>
  </link>

  <joint name="joint_5" type="revolute">
    <parent link="link_4"/>
    <child link="end_effector_link"/>
    <origin xyz="0 0 0.15" rpy="1.5707 0 0"/>
    <axis xyz="0 0 1"/>
    <limit lower="-3.14" upper="3.14" effort="10" velocity="1"/>
  </joint>

</robot>